const HttpError = require('../models/http-error');
const { validationResult } = require('express-validator');
const User = require('../models/user');

const getUsers = async (req, res, next) => {
  let users;
  try {
    users = await User.find({}, '-password').exec();
  } catch (err) {
    const error = new HttpError(
      'Signing up failed, please try again later',
      500
    );
    return next(error);
  }

  res.json({ users });
};

const signUp = async (req, res, next) => {
  const errors = validationResult(req);
  if (!errors.isEmpty()) {

    return next(
      new HttpError('Invalid inputs passed, please check your data', 422)
    );
  }

  const { name, email, password } = req.body;
  let existingUser;
  try {
    existingUser = await User.findOne({ email: email });
  } catch (err) {
    const error = new HttpError(
      'Signing up failed, please try again later',
      500
    );
    return next(error);
  }

  if (existingUser) {
    const error = new HttpError(
      'User exists already, please login instead',
      422
    );
    return next(error);
  }

  const createdUser = new User({
    name,
    email,
    image: req.file.path,
    password,
    places: [],
  });

  try {
    await createdUser.save();
  } catch (err) {
    const error = new HttpError('Signing Up failed, please try again.', 500);
    return next(error);
  }

  res.status(201).json({ createdUser });
};

const login = async (req, res, next) => {
  const { email, password } = req.body;

  try {
    existingUser = await User.findOne({ email: email });
  } catch (err) {
    const error = new HttpError('Login failed, please try again later', 500);
    return next(error);
  }

  if (!existingUser || existingUser.password !== password) {
    return next(
      new HttpError('Could not identify user, credential seem to be wrong', 401)
    );
  }
  res.json({ message: 'Logged In', user:existingUser });
};

exports.signUp = signUp;
exports.getUsers = getUsers;
exports.login = login;
